Workbook

Sheet Summary Dashboard
A1: VSG Rewrite Tracker - Summary Dashboard
A3: Overall Progress
A4: Category | B4: Total Items | C4: Not Started | D4: In Progress | E4: Completed | F4: Progress %
A5: Jobs & Layout Management | B5: 25 | C5: =COUNTIF('Jobs & Layout Management'!G:G,"Not Started") | D5: =COUNTIF('Jobs & Layout Management'!G:G,"In Progress") | E5: =COUNTIF('Jobs & Layout Management'!G:G,"Completed")+COUNTIF('Jobs & Layout Management'!G:G,"Verified") | F5: =IF(B5>0,ROUND((E5/B5)*100,1)&"%","0%")
A6: Analysis & Detection | B6: 65 | C6: =COUNTIF('Analysis & Detection'!G:G,"Not Started") | D6: =COUNTIF('Analysis & Detection'!G:G,"In Progress") | E6: =COUNTIF('Analysis & Detection'!G:G,"Completed")+COUNTIF('Analysis & Detection'!G:G,"Verified") | F6: =IF(B6>0,ROUND((E6/B6)*100,1)&"%","0%")
A7: Track Processing & Extraction | B7: 11 | C7: =COUNTIF('Track Processing & Extraction'!G:G,"Not Started") | D7: =COUNTIF('Track Processing & Extraction'!G:G,"In Progress") | E7: =COUNTIF('Track Processing & Extraction'!G:G,"Completed")+COUNTIF('Track Processing & Extraction'!G:G,"Verified") | F7: =IF(B7>0,ROUND((E7/B7)*100,1)&"%","0%")
A8: Audio Correction | B8: 36 | C8: =COUNTIF('Audio Correction'!G:G,"Not Started") | D8: =COUNTIF('Audio Correction'!G:G,"In Progress") | E8: =COUNTIF('Audio Correction'!G:G,"Completed")+COUNTIF('Audio Correction'!G:G,"Verified") | F8: =IF(B8>0,ROUND((E8/B8)*100,1)&"%","0%")
A9: Subtitle Processing | B9: 652 | C9: =COUNTIF('Subtitle Processing'!G:G,"Not Started") | D9: =COUNTIF('Subtitle Processing'!G:G,"In Progress") | E9: =COUNTIF('Subtitle Processing'!G:G,"Completed")+COUNTIF('Subtitle Processing'!G:G,"Verified") | F9: =IF(B9>0,ROUND((E9/B9)*100,1)&"%","0%")
A10: Orchestrator & Pipeline | B10: 40 | C10: =COUNTIF('Orchestrator & Pipeline'!G:G,"Not Started") | D10: =COUNTIF('Orchestrator & Pipeline'!G:G,"In Progress") | E10: =COUNTIF('Orchestrator & Pipeline'!G:G,"Completed")+COUNTIF('Orchestrator & Pipeline'!G:G,"Verified") | F10: =IF(B10>0,ROUND((E10/B10)*100,1)&"%","0%")
A11: Post-Processing & Auditors | B11: 92 | C11: =COUNTIF('Post-Processing & Auditors'!G:G,"Not Started") | D11: =COUNTIF('Post-Processing & Auditors'!G:G,"In Progress") | E11: =COUNTIF('Post-Processing & Auditors'!G:G,"Completed")+COUNTIF('Post-Processing & Auditors'!G:G,"Verified") | F11: =IF(B11>0,ROUND((E11/B11)*100,1)&"%","0%")
A12: Main Window & Workers | B12: 34 | C12: =COUNTIF('Main Window & Workers'!G:G,"Not Started") | D12: =COUNTIF('Main Window & Workers'!G:G,"In Progress") | E12: =COUNTIF('Main Window & Workers'!G:G,"Completed")+COUNTIF('Main Window & Workers'!G:G,"Verified") | F12: =IF(B12>0,ROUND((E12/B12)*100,1)&"%","0%")
A13: Dialogs | B13: 299 | C13: =COUNTIF('Dialogs'!G:G,"Not Started") | D13: =COUNTIF('Dialogs'!G:G,"In Progress") | E13: =COUNTIF('Dialogs'!G:G,"Completed")+COUNTIF('Dialogs'!G:G,"Verified") | F13: =IF(B13>0,ROUND((E13/B13)*100,1)&"%","0%")
A14: Widgets & Components | B14: 16 | C14: =COUNTIF('Widgets & Components'!G:G,"Not Started") | D14: =COUNTIF('Widgets & Components'!G:G,"In Progress") | E14: =COUNTIF('Widgets & Components'!G:G,"Completed")+COUNTIF('Widgets & Components'!G:G,"Verified") | F14: =IF(B14>0,ROUND((E14/B14)*100,1)&"%","0%")
A15: Config, Models & Utilities | B15: 122 | C15: =COUNTIF('Config, Models & Utilities'!G:G,"Not Started") | D15: =COUNTIF('Config, Models & Utilities'!G:G,"In Progress") | E15: =COUNTIF('Config, Models & Utilities'!G:G,"Completed")+COUNTIF('Config, Models & Utilities'!G:G,"Verified") | F15: =IF(B15>0,ROUND((E15/B15)*100,1)&"%","0%")
A16: TOTAL | B16: =SUM(B5:B15) | C16: =SUM(C5:C15) | D16: =SUM(D5:D15) | E16: =SUM(E5:E15) | F16: =IF(B16>0,ROUND((E16/B16)*100,1)&"%","0%")
A19: Status Legend:
A20: Not Started | B20: Work has not begun
A21: In Progress | B21: Currently being worked on
A22: Completed | B22: Implementation complete
A23: Testing | B23: Under testing/review
A24: Verified | B24: Tested and verified working
A25: Blocked | B25: Blocked by dependency
A27: Priority Legend:
A28: Critical | B28: Core functionality, must implement first
A29: High | B29: Important feature, prioritize
A30: Medium | B30: Standard priority
A31: Low | B31: Nice to have, can defer

Sheet Jobs & Layout Management
A1: Done | B1: File Path | C1: Function/Class/Feature | D1: Type | E1: Description | F1: Features | G1: Status | H1: Priority | I1: Dependencies | J1: Notes | K1: New Implementation Path
B2: vsg_core/job_discovery.py | C2: discover_jobs | D2: Function | E2: Discovers jobs based on a dictionary of source paths. | F2: Handles single file mode, Supports batch processing, Error handling, Path handling | G2: Not Started | H2: Medium
B3: vsg_core/job_layouts/__init__.py | C3: __init__ | D3: Module | E3: Module initialization/configuration | G3: Not Started | H3: High
B4: vsg_core/job_layouts/manager.py | C4: JobLayoutManager | D4: Class | E4: Main orchestrator for handling job layout persistence, copying, and validation. | G4: Not Started | H4: High
B5: vsg_core/job_layouts/manager.py | C5: JobLayoutManager.__init__ | D5: Method | E5: Method of JobLayoutManager | F5: Logging, Path handling | G5: Not Started | H5: High
B6: vsg_core/job_layouts/manager.py | C6: JobLayoutManager._create_enhanced_layout | D6: Method | E6: Adds positional metadata to a layout for robust ordering. | G6: Not Started | H6: Medium
B7: vsg_core/job_layouts/manager.py | C7: JobLayoutManager.cleanup_all | D7: Method | E7: Deletes all temporary layout files and releases cached video resources. | F7: Caching support, Error handling | G7: Not Started | H7: Medium
B8: vsg_core/job_layouts/manager.py | C8: JobLayoutManager.copy_layout_between_jobs | D8: Method | E8: Copies a layout if the source and target files are structurally compatible. | F8: Logging | G8: Not Started | H8: Medium
B9: vsg_core/job_layouts/manager.py | C9: JobLayoutManager.delete_layout | D9: Method | E9: Method of JobLayoutManager | G9: Not Started | H9: Medium
B10: vsg_core/job_layouts/manager.py | C10: JobLayoutManager.generate_job_id | D10: Method | E10: Generates a consistent and unique job ID from source file paths. | F10: Path handling | G10: Not Started | H10: Medium
B11: vsg_core/job_layouts/manager.py | C11: JobLayoutManager.layout_exists | D11: Method | E11: Method of JobLayoutManager | G11: Not Started | H11: Medium
B12: vsg_core/job_layouts/manager.py | C12: JobLayoutManager.load_job_layout | D12: Method | E12: Loads and validates a job layout. | F12: Includes validation, Logging | G12: Not Started | H12: Medium
B13: vsg_core/job_layouts/manager.py | C13: JobLayoutManager.save_job_layout | D13: Method | E13: Saves a job layout, generating fresh signatures and enhancing the layout data. | F13: Error handling, Logging | G13: Not Started | H13: Medium
B14: vsg_core/job_layouts/persistence.py | C14: LayoutPersistence | D14: Class | E14: Handles saving and loading job layouts to/from JSON files. | G14: Not Started | H14: High
B15: vsg_core/job_layouts/persistence.py | C15: LayoutPersistence.__init__ | D15: Method | E15: Method of LayoutPersistence | F15: Logging, Path handling | G15: Not Started | H15: High
B16: vsg_core/job_layouts/persistence.py | C16: LayoutPersistence.cleanup_all | D16: Method | E16: Removes all layout files and the layouts directory. | F16: Error handling, Logging | G16: Not Started | H16: Medium
B17: vsg_core/job_layouts/persistence.py | C17: LayoutPersistence.delete_layout | D17: Method | E17: Deletes a specific layout file. | F17: Error handling, Logging | G17: Not Started | H17: Medium
B18: vsg_core/job_layouts/persistence.py | C18: LayoutPersistence.layout_exists | D18: Method | E18: Checks if a layout file exists. | G18: Not Started | H18: Medium
B19: vsg_core/job_layouts/persistence.py | C19: LayoutPersistence.load_layout | D19: Method | E19: Loads a job layout from a JSON file. | F19: Error handling, Logging, JSON handling | G19: Not Started | H19: Medium
B20: vsg_core/job_layouts/persistence.py | C20: LayoutPersistence.save_layout | D20: Method | E20: Saves a job layout using a temporary file to prevent corruption. | F20: Error handling, Logging, JSON handling | G20: Not Started | H20: Medium
B21: vsg_core/job_layouts/signature.py | C21: EnhancedSignatureGenerator | D21: Class | E21: Generates robust signatures for track matching and layout compatibility. | G21: Not Started | H21: High
B22: vsg_core/job_layouts/signature.py | C22: EnhancedSignatureGenerator.generate_structure_signature | D22: Method | E22: Generates a detailed, order-sensitive signature of the file structure. | F22: JSON handling | G22: Not Started | H22: Medium
B23: vsg_core/job_layouts/signature.py | C23: EnhancedSignatureGenerator.generate_track_signature | D23: Method | E23: Generates a basic signature for a set of tracks. | G23: Not Started | H23: Medium
B24: vsg_core/job_layouts/signature.py | C24: EnhancedSignatureGenerator.structures_are_compatible | D24: Method | E24: Compares two structure signatures for exact compatibility. | G24: Not Started | H24: Medium
B25: vsg_core/job_layouts/validation.py | C25: LayoutValidator | D25: Class | E25: Validates that loaded layout data is well-formed. | G25: Not Started | H25: High
B26: vsg_core/job_layouts/validation.py | C26: LayoutValidator.validate | D26: Method | E26: Validates the structure and content of a layout data dictionary. | F26: Includes validation | G26: Not Started | H26: Medium

Sheet Analysis & Detection
A1: Done | B1: File Path | C1: Function/Class/Feature | D1: Type | E1: Description | F1: Features | G1: Status | H1: Priority | I1: Dependencies | J1: Notes | K1: New Implementation Path
B2: vsg_core/analysis/__init__.py | C2: __init__ | D2: Module | E2: Module initialization/configuration | G2: Not Started | H2: High
B3: vsg_core/analysis/audio_corr.py | C3: _apply_bandpass | D3: Function | E3: Applies a Butterworth band-pass filter to isolate dialogue frequencies. | F3: Error handling, Logging, UI component | G3: Not Started | H3: Medium
B4: vsg_core/analysis/audio_corr.py | C4: _apply_lowpass | D4: Function | E4: Applies a simple FIR low-pass filter. | F4: Error handling, Logging | G4: Not Started | H4: Medium
B5: vsg_core/analysis/audio_corr.py | C5: _decode_to_memory | D5: Function | E5: Decodes one audio stream to a mono float32 NumPy array. | F5: Supports batch processing, Error handling, Logging, FFmpeg integration, Path handling | G5: Not Started | H5: Medium
B6: vsg_core/analysis/audio_corr.py | C6: _find_delay_dtw | D6: Function | E6: Calculates delay using Dynamic Time Warping on MFCC features. | F6: Error handling, Path handling | G6: Not Started | H6: Medium
B7: vsg_core/analysis/audio_corr.py | C7: _find_delay_gcc_phat | D7: Function | E7: Calculates delay using Generalized Cross-Correlation with Phase Transform. | G7: Not Started | H7: Medium
B8: vsg_core/analysis/audio_corr.py | C8: _find_delay_gcc_scot | D8: Function | E8: Calculates delay using GCC-SCOT (Smoothed Coherence Transform). | F8: Qt signals | G8: Not Started | H8: Medium
B9: vsg_core/analysis/audio_corr.py | C9: _find_delay_gcc_whiten | D9: Function | E9: Calculates delay using GCC with Spectral Whitening (Whitened Cross-Correlation). | F9: Qt signals | G9: Not Started | H9: Medium
B10: vsg_core/analysis/audio_corr.py | C10: _find_delay_onset | D10: Function | E10: Calculates delay using onset detection envelope correlation. | F10: Error handling | G10: Not Started | H10: Medium
B11: vsg_core/analysis/audio_corr.py | C11: _find_delay_scc | D11: Function | E11: Calculates delay and match percentage using standard cross-correlation. | G11: Not Started | H11: Medium
B12: vsg_core/analysis/audio_corr.py | C12: _find_delay_spectrogram | D12: Function | E12: Calculates delay using spectrogram cross-correlation. | F12: Error handling, Logging, Qt signals | G12: Not Started | H12: Medium
B13: vsg_core/analysis/audio_corr.py | C13: _normalize_lang | D13: Function | E13: Module-level function | G13: Not Started | H13: Medium
B14: vsg_core/analysis/audio_corr.py | C14: _normalize_peak_confidence | D14: Function | E14: Normalizes peak confidence by comparing to noise floor and second-best peak. | F14: Qt signals | G14: Not Started | H14: Medium
B15: vsg_core/analysis/audio_corr.py | C15: _run_method_on_chunks | D15: Function | E15: Runs a specific correlation method on pre-extracted chunks. | F15: Logging | G15: Not Started | H15: High
B16: vsg_core/analysis/audio_corr.py | C16: get_audio_stream_info | D16: Function | E16: Finds the best audio stream and returns its 0-based index and mkvmerge track ID. | F16: Fallback handling, Error handling, MKVToolNix integration, JSON handling, Path handling | G16: Not Started | H16: Medium
B17: vsg_core/analysis/audio_corr.py | C17: run_audio_correlation | D17: Function | E17: Runs audio correlation analysis between reference and target files. | F17: Supports batch processing, Multi-threaded, Error handling, Logging, FFmpeg integration | G17: Not Started | H17: High
B18: vsg_core/analysis/audio_corr.py | C18: run_multi_correlation | D18: Function | E18: Runs multiple correlation methods on the same audio chunks for comparison. | F18: Supports batch processing, Error handling, Logging, FFmpeg integration, Path handling | G18: Not Started | H18: High
B19: vsg_core/analysis/drift_detection.py | C19: _analyze_transition_patterns | D19: Function | E19: Analyzes and reports patterns in delay transitions | F19: Logging | G19: Not Started | H19: Medium
B20: vsg_core/analysis/drift_detection.py | C20: _build_cluster_diagnostics | D20: Function | E20: Builds detailed cluster composition and transition analysis. | F20: Logging | G20: Not Started | H20: Medium
B21: vsg_core/analysis/drift_detection.py | C21: _filter_clusters | D21: Function | E21: Filters clusters based on quality validation. | F21: Includes validation | G21: Not Started | H21: Medium
B22: vsg_core/analysis/drift_detection.py | C22: _format_chunk_range | D22: Function | E22: Formats chunk numbers as ranges (e.g., '1-3,5-25,30-48') | G22: Not Started | H22: Medium
B23: vsg_core/analysis/drift_detection.py | C23: _get_quality_thresholds | D23: Function | E23: Returns quality validation thresholds based on the selected quality mode. | F23: Includes validation | G23: Not Started | H23: Medium
B24: vsg_core/analysis/drift_detection.py | C24: _get_video_framerate | D24: Function | E24: Uses ffprobe to get the video's average frame rate. | F24: Error handling, FFmpeg integration, Path handling | G24: Not Started | H24: Medium
B25: vsg_core/analysis/drift_detection.py | C25: _validate_cluster | D25: Function | E25: Validates a single cluster against quality thresholds. | F25: Includes validation | G25: Not Started | H25: Medium
B26: vsg_core/analysis/drift_detection.py | C26: diagnose_audio_issue | D26: Function | E26: Analyzes correlation chunks to diagnose the type of sync issue. | F26: Includes validation, Fallback handling, Logging, Path handling | G26: Not Started | H26: Medium
B27: vsg_core/analysis/source_separation.py | C27: _collect_models_from_dict | D27: Function | E27: Module-level function | G27: Not Started | H27: Medium
B28: vsg_core/analysis/source_separation.py | C28: _collect_models_from_list | D28: Function | E28: Module-level function | G28: Not Started | H28: Medium
B29: vsg_core/analysis/source_separation.py | C29: _enrich_model_with_quality_data | D29: Function | E29: Enrich model metadata with quality database information. | G29: Not Started | H29: Medium
B30: vsg_core/analysis/source_separation.py | C30: _extract_models_from_registry | D30: Function | E30: Recursively extract model info from audio-separator's nested JSON structure. | G30: Not Started | H30: Medium
B31: vsg_core/analysis/source_separation.py | C31: _extract_sdr_from_filename | D31: Function | E31: Extract SDR scores from model filename if embedded. | G31: Not Started | H31: Medium
B32: vsg_core/analysis/source_separation.py | C32: _fallback_models | D32: Function | E32: Module-level function | F32: Fallback handling | G32: Not Started | H32: Medium
B33: vsg_core/analysis/source_separation.py | C33: _get_venv_python | D33: Function | E33: Get the correct Python executable from the current virtual environment. | F33: Path handling | G33: Not Started | H33: Medium
B34: vsg_core/analysis/source_separation.py | C34: _load_model_data | D34: Function | E34: Module-level function | F34: Error handling, JSON handling | G34: Not Started | H34: Medium
B35: vsg_core/analysis/source_separation.py | C35: _load_model_data_via_cli | D35: Function | E35: Module-level function | F35: Error handling, Subprocess execution, JSON handling, Path handling | G35: Not Started | H35: Medium
B36: vsg_core/analysis/source_separation.py | C36: _log_separator_stderr | D36: Function | E36: Module-level function | F36: Error handling, Logging | G36: Not Started | H36: Medium
B37: vsg_core/analysis/source_separation.py | C37: _module_available_in_python | D37: Function | E37: Module-level function | F37: Error handling, Subprocess execution | G37: Not Started | H37: Medium
B38: vsg_core/analysis/source_separation.py | C38: _read_audio_file | D38: Function | E38: Read audio file and return (sample_rate, mono float32 array). | F38: Path handling | G38: Not Started | H38: Medium
B39: vsg_core/analysis/source_separation.py | C39: _resolve_separation_settings | D39: Function | E39: Module-level function | G39: Not Started | H39: Medium
B40: vsg_core/analysis/source_separation.py | C40: _select_model_filename | D40: Function | E40: Module-level function | G40: Not Started | H40: Medium
...

Sheet Track Processing & Extraction
A1: Done | B1: File Path | C1: Function/Class/Feature | D1: Type | E1: Description | F1: Features | G1: Status | H1: Priority | I1: Dependencies | J1: Notes | K1: New Implementation Path
B2: vsg_core/extraction/attachments.py | C2: extract_attachments | D2: Function | E2: Module-level function | F2: Supports batch processing, Fallback handling, Logging, MKVToolNix integration, Path handling | G2: Not Started | H2: Medium
B3: vsg_core/extraction/tracks.py | C3: _build_track_description | D3: Function | E3: Builds a rich, MediaInfo-like description string from combined track info. | F3: Error handling, FFmpeg integration | G3: Not Started | H3: Medium
B4: vsg_core/extraction/tracks.py | C4: _ext_for_codec | D4: Function | E4: Module-level function | G4: Not Started | H4: Medium
B5: vsg_core/extraction/tracks.py | C5: _get_channel_layout_str | D5: Function | E5: Gets a friendly channel layout string. | G5: Not Started | H5: Medium
B6: vsg_core/extraction/tracks.py | C6: _get_detailed_stream_info | D6: Function | E6: Module-level function | F6: Error handling, Logging, FFmpeg integration, JSON handling, Path handling | G6: Not Started | H6: Medium
B7: vsg_core/extraction/tracks.py | C7: _parse_pcm_codec_name | D7: Function | E7: Parses an ffprobe pcm codec name like 'pcm_s24le' into a readable string. | F7: FFmpeg integration | G7: Not Started | H7: Medium
B8: vsg_core/extraction/tracks.py | C8: _pcm_codec_from_bit_depth | D8: Function | E8: Module-level function | F8: Error handling | G8: Not Started | H8: Medium
B9: vsg_core/extraction/tracks.py | C9: extract_tracks | D9: Function | E9: Extract tracks from MKV with enhanced error detection. | F9: Error handling, Logging, FFmpeg integration, MKVToolNix integration, Path handling | G9: Not Started | H9: Medium
B10: vsg_core/extraction/tracks.py | C10: get_stream_info | D10: Function | E10: Module-level function | F10: Error handling, Logging, MKVToolNix integration, JSON handling, Path handling | G10: Not Started | H10: Medium
B11: vsg_core/extraction/tracks.py | C11: get_stream_info_with_delays | D11: Function | E11: Get stream info including container delays from mkvmerge -J output. | F11: Error handling, Logging, MKVToolNix integration, JSON handling, Path handling | G11: Not Started | H11: Medium
B12: vsg_core/extraction/tracks.py | C12: get_track_info_for_dialog | D12: Function | E12: Module-level function | F12: Logging, FFmpeg integration, MKVToolNix integration, Path handling, UI component | G12: Not Started | H12: Medium

Sheet Audio Correction
A1: Done | B1: File Path | C1: Function/Class/Feature | D1: Type | E1: Description | F1: Features | G1: Status | H1: Priority | I1: Dependencies | J1: Notes | K1: New Implementation Path
B2: vsg_core/correction/__init__.py | C2: __init__ | D2: Module | E2: Module initialization/configuration | G2: Not Started | H2: High
B3: vsg_core/correction/linear.py | C3: _get_sample_rate | D3: Function | E3: Helper to get the sample rate of the first audio stream. | F3: Error handling, Logging, FFmpeg integration, JSON handling, Path handling | G3: Not Started | H3: Medium
B4: vsg_core/correction/linear.py | C4: run_linear_correction | D4: Function | E4: Corrects constant audio drift by resampling the audio speed. | F4: Error handling, Logging, FFmpeg integration, Path handling | G4: Not Started | H4: High
B5: vsg_core/correction/pal.py | C5: run_pal_correction | D5: Function | E5: Corrects audio drift due to PAL speed-up using a pitch-corrected resample. | F5: Error handling, Logging, FFmpeg integration, Path handling | G5: Not Started | H5: High
B6: vsg_core/correction/stepping.py | C6: AudioSegment | D6: Class | E6: Represents an action point on the target timeline for the assembly function. | G6: Not Started | H6: High
B7: vsg_core/correction/stepping.py | C7: CorrectionResult | D7: Class | E7: Class definition | G7: Not Started | H7: High
B8: vsg_core/correction/stepping.py | C8: CorrectionVerdict | D8: Class | E8: Class definition | G8: Not Started | H8: High
B9: vsg_core/correction/stepping.py | C9: SteppingCorrector | D9: Class | E9: Class definition | G9: Not Started | H9: High
B10: vsg_core/correction/stepping.py | C10: _get_audio_properties | D10: Function | E10: Module-level function | F10: Error handling, FFmpeg integration, JSON handling, Path handling | G10: Not Started | H10: Medium
B11: vsg_core/correction/stepping.py | C11: generate_edl_from_correlation | D11: Function | E11: Generate a simplified EDL from correlation chunks for subtitle adjustment. | F11: Includes validation, Logging | G11: Not Started | H11: Medium
B12: vsg_core/correction/stepping.py | C12: run_stepping_correction | D12: Function | E12: Module-level function | F12: Includes validation, Fallback handling, Error handling, Logging, Path handling | G12: Not Started | H12: High
B13: vsg_core/correction/stepping.py | C13: SteppingCorrector.__init__ | D13: Method | E13: Method of SteppingCorrector | F13: Logging, Path handling | G13: Not Started | H13: High
B14: vsg_core/correction/stepping.py | C14: SteppingCorrector._analyze_internal_drift | D14: Method | E14: Method of SteppingCorrector | F14: Error handling, Logging, UI component | G14: Not Started | H14: Medium
B15: vsg_core/correction/stepping.py | C15: SteppingCorrector._assemble_from_segments_via_ffmpeg | D15: Method | E15: Method of SteppingCorrector | F15: Error handling, Logging, FFmpeg integration, Path handling | G15: Not Started | H15: Medium
B16: vsg_core/correction/stepping.py | C16: SteppingCorrector._decode_to_memory | D16: Method | E16: Method of SteppingCorrector | F16: Supports batch processing, Error handling, Logging, FFmpeg integration, Path handling | G16: Not Started | H16: Medium
B17: vsg_core/correction/stepping.py | C17: SteppingCorrector._detect_speech_regions_vad | D17: Method | E17: Detect speech regions using Voice Activity Detection (WebRTC VAD). | F17: Error handling, Logging, UI component | G17: Not Started | H17: Medium
B18: vsg_core/correction/stepping.py | C18: SteppingCorrector._detect_transients | D18: Method | E18: Detect transients (sudden amplitude increases like musical beats/impacts). | F18: Logging, UI component | G18: Not Started | H18: Medium
B19: vsg_core/correction/stepping.py | C19: SteppingCorrector._extract_content_from_reference | D19: Method | E19: Attempts to extract matching content from reference audio to fill a gap. | F19: Logging, UI component | G19: Not Started | H19: Medium
B20: vsg_core/correction/stepping.py | C20: SteppingCorrector._filter_coarse_map_by_clusters | D20: Method | E20: Filters coarse_map to remove entries that fall within invalid clusters. | F20: Includes validation, Fallback handling, Logging | G20: Not Started | H20: Medium
B21: vsg_core/correction/stepping.py | C21: SteppingCorrector._find_boundary_in_zone | D21: Method | E21: Finds the precise boundary where audio delay changes from delay_before to delay_after. | F21: Includes validation, Logging, Path handling, UI component | G21: Not Started | H21: Medium
... B32: vsg_core/correction/stepping.py | C32: SteppingCorrector.run | D32: Method | E32: Method of SteppingCorrector | F32: Error handling, Logging, FFmpeg integration, Path handling | G32: Not Started | H32: High
B33: vsg_core/orchestrator/steps/audio_correction_step.py | C33: AudioCorrectionStep | D33: Class | E33: Acts as a router to apply the correct audio correction based on the | G33: Not Started | H33: High
B34: vsg_core/orchestrator/steps/audio_correction_step.py | C34: AudioCorrectionStep._validate_linear_correction | D34: Method | E34: Validate that linear drift correction was applied successfully. | F34: Includes validation, Error handling, Logging, Path handling | G34: Not Started | H34: Medium
B35: vsg_core/orchestrator/steps/audio_correction_step.py | C35: AudioCorrectionStep._validate_pal_correction | D35: Method | E35: Validate that PAL correction was applied successfully. | F35: Includes validation, Error handling, Logging, Path handling | G35: Not Started | H35: Medium
B36: vsg_core/orchestrator/steps/audio_correction_step.py | C36: AudioCorrectionStep._validate_stepping_correction | D36: Method | E36: Validate that stepping correction was applied successfully. | F36: Includes validation, Error handling, Logging, Path handling | G36: Not Started | H36: Medium
B37: vsg_core/orchestrator/steps/audio_correction_step.py | C37: AudioCorrectionStep.run | D37: Method | E37: Method of AudioCorrectionStep | F37: Includes validation, Error handling, Logging | G37: Not Started | H37: High

Sheet Subtitle Processing
A1: Done | B1: File Path | C1: Function/Class/Feature | D1: Type | E1: Description | F1: Features | G1: Status | H1: Priority | I1: Dependencies | J1: Notes | K1: New Implementation Path
B2: vsg_core/orchestrator/steps/subtitles_step.py | C2: SubtitlesStep | D2: Class | E2: Unified subtitle processing step. | G2: Not Started | H2: High
B3: vsg_core/orchestrator/steps/subtitles_step.py | C3: _check_timestamp_precision | D3: Function | E3: Check the precision of a timestamp string (number of fractional digits). | F3: Error handling | G3: Not Started | H3: Medium
B4: vsg_core/orchestrator/steps/subtitles_step.py | C4: _parse_ass_time_str | D4: Function | E4: Parse ASS timestamp string to float ms (same logic as SubtitleData). | F4: Error handling, Logging | G4: Not Started | H4: Medium
B5: vsg_core/orchestrator/steps/subtitles_step.py | C5: _read_raw_ass_timestamps | D5: Function | E5: Read raw timestamp strings from an ASS file without full parsing. | F5: Error handling, Logging, Path handling, UI component | G5: Not Started | H5: Medium
B6: vsg_core/orchestrator/steps/subtitles_step.py | C6: SubtitlesStep._apply_sync_unified | D6: Method | E6: Apply sync mode using unified SubtitleData flow. | F6: Caching support, Error handling, Logging, Path handling | G6: Not Started | H6: Medium
B7: vsg_core/orchestrator/steps/subtitles_step.py | C7: SubtitlesStep._get_ocr_debug_dir | D7: Method | E7: Get OCR debug directory for a track if it exists. | F7: Error handling, Logging, Path handling | G7: Not Started | H7: Medium
B8: vsg_core/orchestrator/steps/subtitles_step.py | C8: SubtitlesStep._get_video_resolution | D8: Method | E8: Get video resolution for rescaling. | F8: Error handling, Logging, Path handling | G8: Not Started | H8: Medium
B9: vsg_core/orchestrator/steps/subtitles_step.py | C9: SubtitlesStep._process_ocr | D9: Method | E9: Process OCR for a track. | F9: Error handling, Logging, Subprocess execution, Path handling | G9: Not Started | H9: Medium
B10: vsg_core/orchestrator/steps/subtitles_step.py | C10: SubtitlesStep._process_track_unified | D10: Method | E10: Process a subtitle track using the unified SubtitleData flow. | F10: Caching support, Includes validation, Error handling, Logging, MKVToolNix integration | G10: Not Started | H10: Medium
B11: vsg_core/orchestrator/steps/subtitles_step.py | C11: SubtitlesStep._run_ocr_subprocess | D11: Method | E11: Method of SubtitlesStep | F11: Error handling, Logging, Subprocess execution, JSON handling, Path handling | G11: Not Started | H11: High
B12: vsg_core/orchestrator/steps/subtitles_step.py | C12: SubtitlesStep.run | D12: Method | E12: Method of SubtitlesStep | F12: Caching support, Fallback handling, Error handling, Logging, Path handling | G12: Not Started | H12: High
B13: vsg_core/postprocess/auditors/subtitle_formats.py | C13: SubtitleFormatsAuditor | D13: Class | E13: Validates subtitle conversions and all processing steps. | G13: Not Started | H13: High
B14: vsg_core/postprocess/auditors/subtitle_formats.py | C14: SubtitleFormatsAuditor._verify_ass_conversion | D14: Method | E14: Verify subtitle was converted to ASS/SSA format. | F14: Logging | G14: Not Started | H14: Medium
B15: vsg_core/postprocess/auditors/subtitle_formats.py | C15: SubtitleFormatsAuditor._verify_font_size | D15: Method | E15: Verify font size multiplier was applied. | F15: Error handling, Logging, Path handling | G15: Not Started | H15: Medium
B16: vsg_core/postprocess/auditors/subtitle_formats.py | C16: SubtitleFormatsAuditor._verify_ocr | D16: Method | E16: Verify OCR was performed and resulted in text format. | F16: Logging | G16: Not Started | H16: Medium
B17: vsg_core/postprocess/auditors/subtitle_formats.py | C17: SubtitleFormatsAuditor._verify_rescaling | D17: Method | E17: Verify PlayResX/PlayResY were updated to match video resolution. | F17: Error handling, Logging, FFmpeg integration, Path handling | G17: Not Started | H17: Medium
B18: vsg_core/postprocess/auditors/subtitle_formats.py | C18: SubtitleFormatsAuditor.run | D18: Method | E18: Comprehensive subtitle audit including: | F18: Includes validation, Fallback handling, Error handling, Logging, FFmpeg integration | G18: Not Started | H18: High
B19: vsg_core/subtitles/__init__.py | C19: __init__ | D19: Module | E19: Module initialization/configuration | G19: Not Started | H19: High
B20: vsg_core/subtitles/checkpoint_selection.py | C20: select_smart_checkpoints | D20: Function | E20: Smart checkpoint selection: avoid OP/ED, prefer dialogue events. | F20: Logging, UI component | G20: Not Started | H20: Medium
B21: vsg_core/subtitles/convert.py | C21: convert_srt_to_ass | D21: Function | E21: Module-level function | F21: Logging, FFmpeg integration, Path handling | G21: Not Started | H21: Medium
B22: vsg_core/subtitles/data.py | C22: EmbeddedFont | D22: Class | E22: Embedded font from [Fonts] section. | G22: Not Started | H22: High
B23: vsg_core/subtitles/data.py | C23: EmbeddedGraphic | D23: Class | E23: Embedded graphic from [Graphics] section. | G23: Not Started | H23: High
B24: vsg_core/subtitles/data.py | C24: NumpyEncoder | D24: Class | E24: JSON encoder that handles numpy types. | G24: Not Started | H24: High
B25: vsg_core/subtitles/data.py | C25: OCREventData | D25: Class | E25: OCR-specific metadata for a single subtitle event. | G25: Not Started | H25: High
B26: vsg_core/subtitles/data.py | C26: OCRMetadata | D26: Class | E26: Document-level OCR metadata and statistics. | G26: Not Started | H26: High
B27: vsg_core/subtitles/data.py | C27: OperationRecord | D27: Class | E27: Record of an operation applied to subtitle data. | G27: Not Started | H27: High
B28: vsg_core/subtitles/data.py | C28: OperationResult | D28: Class | E28: Result of applying an operation. | G28: Not Started | H28: High
B29: vsg_core/subtitles/data.py | C29: SteppingEventData | D29: Class | E29: Stepping-specific metadata for a single subtitle event. | G29: Not Started | H29: High
B30: vsg_core/subtitles/data.py | C30: SubtitleData | D30: Class | E30: Universal subtitle data container. | G30: Not Started | H30: High
B31: vsg_core/subtitles/data.py | C31: SubtitleEvent | D31: Class | E31: Single subtitle event with FLOAT MILLISECOND timing. | G31: Not Started | H31: High
B32: vsg_core/subtitles/data.py | C32: SubtitleStyle | D32: Class | E32: ASS/SSA style definition with all 23 fields. | G32: Not Started | H32: High
B33: vsg_core/subtitles/data.py | C33: SyncEventData | D33: Class | E33: Sync-specific metadata for a single subtitle event. | G33: Not Started | H33: High
... B35: vsg_core/subtitles/data.py | C35: _format_number | D35: Function | E35: Format number, removing unnecessary decimals. | G35: Not Started | H35: Medium
B36: vsg_core/subtitles/data.py | C36: _parse_ass_time | D36: Function | E36: Parse ASS timestamp to float milliseconds. | F36: Error handling | G36: Not Started | H36: Medium
B37: vsg_core/subtitles/data.py | C37: EmbeddedFont.to_dict | D37: Method | E37: Method of EmbeddedFont | G37: Not Started | H37: Medium
B38: vsg_core/subtitles/data.py | C38: EmbeddedGraphic.to_dict | D38: Method | E38: Method of EmbeddedGraphic | G38: Not Started | H38: Medium
B39: vsg_core/subtitles/data.py | C39: NumpyEncoder.default | D39: Method | E39: Method of NumpyEncoder | G39: Not Started | H39: Medium
B40: vsg_core/subtitles/data.py | C40: OCREventData.from_dict | D40: Method | E40: Method of OCREventData | G40: Not Started | H40: Medium
B41: vsg_core/subtitles/data.py | C41: OCREventData.to_dict | D41: Method | E41: Method of OCREventData | G41: Not Started | H41: Medium
...

Sheet Orchestrator & Pipeline
A1: Done | B1: File Path | C1: Function/Class/Feature | D1: Type | E1: Description | F1: Features | G1: Status | H1: Priority | I1: Dependencies | J1: Notes | K1: New Implementation Path
B2: vsg_core/orchestrator/pipeline.py | C2: Orchestrator | D2: Class | E2: Runs the modular steps in order with validation at each stage. | G2: Not Started | H2: High
B3: vsg_core/orchestrator/pipeline.py | C3: Orchestrator.run | D3: Method | E3: Executes the pipeline steps with validation. | F3: Includes validation, Error handling, Logging, Path handling | G3: Not Started | H3: High
B4: vsg_core/orchestrator/steps/__init__.py | C4: __init__ | D4: Module | E4: Module initialization/configuration | G4: Not Started | H4: High
B5: vsg_core/orchestrator/steps/attachments_step.py | C5: AttachmentsStep | D5: Class | E5: Extracts attachments from all sources specified by the user in the UI. | G5: Not Started | H5: High
B6: vsg_core/orchestrator/steps/attachments_step.py | C6: AttachmentsStep._add_replacement_fonts | D6: Method | E6: Copy replacement fonts from Font Manager to temp directory and add to attachments. | F6: Error handling, Logging, Path handling | G6: Not Started | H6: Medium
B7: vsg_core/orchestrator/steps/attachments_step.py | C7: AttachmentsStep.run | D7: Method | E7: Method of AttachmentsStep | F7: Logging, Path handling | G7: Not Started | H7: High
B8: vsg_core/orchestrator/steps/chapters_step.py | C8: ChaptersStep | D8: Class | E8: Extracts/modifies chapter XML from Source 1. | G8: Not Started | H8: High
B9: vsg_core/orchestrator/steps/chapters_step.py | C9: ChaptersStep.run | D9: Method | E9: Method of ChaptersStep | F9: Error handling, Logging, MKVToolNix integration, Path handling | G9: Not Started | H9: High
B10: vsg_core/orchestrator/steps/context.py | C10: Context | D10: Class | E10: Class definition | G10: Not Started | H10: High
B11: vsg_core/orchestrator/steps/extract_step.py | C11: ExtractStep | D11: Class | E11: Class definition | G11: Not Started | H11: High
B12: vsg_core/orchestrator/steps/extract_step.py | C12: ExtractStep._process_generated_tracks | D12: Method | E12: Prepare generated tracks by copying source files. | F12: Includes validation, Error handling, Logging, Path handling | G12: Not Started | H12: Medium
B13: vsg_core/orchestrator/steps/extract_step.py | C13: ExtractStep.run | D13: Method | E13: Method of ExtractStep | F13: Error handling, Logging, FFmpeg integration, MKVToolNix integration, JSON handling | G13: Not Started | H13: High
B14: vsg_core/orchestrator/steps/mux_step.py | C14: MuxStep | D14: Class | E14: Builds mkvmerge tokens and stores them on the context. | G14: Not Started | H14: High
B15: vsg_core/orchestrator/steps/mux_step.py | C15: MuxStep.run | D15: Method | E15: Method of MuxStep | F15: MKVToolNix integration, Path handling | G15: Not Started | H15: High
B16: vsg_core/orchestrator/validation.py | C16: PipelineValidationError | D16: Class | E16: Raised when a pipeline step validation fails. | G16: Not Started | H16: High
B17: vsg_core/orchestrator/validation.py | C17: StepValidator | D17: Class | E17: Validates that pipeline steps completed successfully. | G17: Not Started | H17: High
B18: vsg_core/orchestrator/validation.py | C18: StepValidator.validate_analysis | D18: Method | E18: Validates analysis step results. | F18: Includes validation, Error handling | G18: Not Started | H18: Medium
B19: vsg_core/orchestrator/validation.py | C19: StepValidator.validate_correction | D19: Method | E19: Validates audio correction results. | F19: Includes validation, Error handling, Path handling | G19: Not Started | H19: Medium
B20: vsg_core/orchestrator/validation.py | C20: StepValidator.validate_extraction | D20: Method | E20: Validates extraction step results. | F20: Includes validation, Error handling, MKVToolNix integration, Path handling | G20: Not Started | H20: Medium
B21: vsg_core/orchestrator/validation.py | C21: StepValidator.validate_mux | D21: Method | E21: Validates merge planning results. | F21: Includes validation, Error handling, MKVToolNix integration, Path handling | G21: Not Started | H21: Medium
B22: vsg_core/orchestrator/validation.py | C22: StepValidator.validate_subtitles | D22: Method | E22: Validates subtitle processing results. | F22: Includes validation, Error handling, Path handling | G22: Not Started | H22: Medium
B23: vsg_core/pipeline.py | C23: JobPipeline | D23: Class | E23: Orchestrates video sync job execution. | G23: Not Started | H23: High
B24: vsg_core/pipeline.py | C24: JobPipeline.__init__ | D24: Method | E24: Initializes the job pipeline. | F24: Logging, Path handling | G24: Not Started | H24: High
B25: vsg_core/pipeline.py | C25: JobPipeline.run_job | D25: Method | E25: Runs a complete sync job. | F25: Caching support, Includes validation, Error handling, Logging, MKVToolNix integration | G25: Not Started | H25: High
B26: vsg_core/pipeline_components/__init__.py | C26: __init__ | D26: Module | E26: Module initialization/configuration | G26: Not Started | H26: High
B27: vsg_core/pipeline_components/log_manager.py | C27: LogManager | D27: Class | E27: Manages logging setup and cleanup for jobs. | G27: Not Started | H27: High
B28: vsg_core/pipeline_components/log_manager.py | C28: LogManager.cleanup_log | D28: Method | E28: Cleans up logger and handler resources. | F28: Logging | G28: Not Started | H28: Medium
B29: vsg_core/pipeline_components/log_manager.py | C29: LogManager.setup_job_log | D29: Method | E29: Sets up logging for a job. | F29: Logging, Path handling | G29: Not Started | H29: Medium
B30: vsg_core/pipeline_components/output_writer.py | C30: OutputWriter | D30: Class | E30: Writes output files and mkvmerge configuration. | G30: Not Started | H30: High
B31: vsg_core/pipeline_components/output_writer.py | C31: OutputWriter.prepare_output_path | D31: Method | E31: Prepares the final output path. | F31: Path handling | G31: Not Started | H31: Medium
B32: vsg_core/pipeline_components/output_writer.py | C32: OutputWriter.write_mkvmerge_options | D32: Method | E32: Writes mkvmerge options to a JSON file. | F32: Error handling, Logging, MKVToolNix integration, JSON handling, Path handling | G32: Not Started | H32: Medium
B33: vsg_core/pipeline_components/result_auditor.py | C33: ResultAuditor | D33: Class | E33: Audits merged output files for quality and correctness. | G33: Not Started | H33: High
B34: vsg_core/pipeline_components/result_auditor.py | C34: ResultAuditor.audit_output | D34: Method | E34: Audits the merged output file. | F34: Error handling, Logging, Path handling | G34: Not Started | H34: Medium
B35: vsg_core/pipeline_components/sync_executor.py | C35: SyncExecutor | D35: Class | E35: Executes sync merges and finalizes output. | G35: Not Started | H35: High
B36: vsg_core/pipeline_components/sync_executor.py | C36: SyncExecutor.execute_merge | D36: Method | E36: Executes mkvmerge with the provided options file. | F36: MKVToolNix integration, Path handling | G36: Not Started | H36: Medium
B37: vsg_core/pipeline_components/sync_executor.py | C37: SyncExecutor.finalize_output | D37: Method | E37: Finalizes the merged output file. | F37: Path handling | G37: Not Started | H37: Medium
B38: vsg_core/pipeline_components/sync_planner.py | C38: SyncPlanner | D38: Class | E38: Plans sync operations by delegating to the Orchestrator. | G38: Not Started | H38: High
B39: vsg_core/pipeline_components/sync_planner.py | C39: SyncPlanner.plan_sync | D39: Method | E39: Plans the sync operation by analyzing sources and preparing merge tokens. | F39: Logging, MKVToolNix integration, Path handling | G39: Not Started | H39: Medium
B40: vsg_core/pipeline_components/tool_validator.py | C40: ToolValidator | D40: Class | E40: Validates and locates required external tools. | G40: Not Started | H40: High
...

Sheet Post-Processing & Auditors
A1: Done | B1: File Path | C1: Function/Class/Feature | D1: Type | E1: Description | F1: Features | G1: Status | H1: Priority | I1: Dependencies | J1: Notes | K1: New Implementation Path
B2: vsg_core/audit/__init__.py | C2: __init__ | D2: Module | E2: Module initialization/configuration | G2: Not Started | H2: High
B3: vsg_core/audit/trail.py | C3: AuditTrail | D3: Class | E3: Manages the pipeline audit trail JSON file. | G3: Not Started | H3: High
B4: vsg_core/audit/trail.py | C4: NumpyJSONEncoder | D4: Class | E4: JSON encoder that handles numpy types and Path objects. | G4: Not Started | H4: High
B5: vsg_core/audit/trail.py | C5: AuditTrail.__init__ | D5: Method | E5: Initialize audit trail. | F5: Path handling | G5: Not Started | H5: High
B6: vsg_core/audit/trail.py | C6: AuditTrail._get_nested | D6: Method | E6: Get value at nested path, or None if not found. | F6: Path handling | G6: Not Started | H6: Medium
B7: vsg_core/audit/trail.py | C7: AuditTrail._write | D7: Method | E7: Write audit trail to disk using atomic write pattern. | F7: Error handling, JSON handling, Path handling | G7: Not Started | H7: Medium
B8: vsg_core/audit/trail.py | C8: AuditTrail.append | D8: Method | E8: Append a value to a list at the specified path. | F8: Path handling | G8: Not Started | H8: Medium
B9: vsg_core/audit/trail.py | C9: AuditTrail.append_event | D9: Method | E9: Append a timestamped event to the events log. | F9: Error handling, Logging | G9: Not Started | H9: Medium
B10: vsg_core/audit/trail.py | C10: AuditTrail.finalize | D10: Method | E10: Finalize the audit trail. | F10: Path handling | G10: Not Started | H10: Medium
B11: vsg_core/audit/trail.py | C11: AuditTrail.get_path | D11: Method | E11: Return path to the audit trail file. | F11: Path handling | G11: Not Started | H11: Medium
B12: vsg_core/audit/trail.py | C12: AuditTrail.record | D12: Method | E12: Record a value at the specified path. | F12: Error handling, Path handling | G12: Not Started | H12: Medium
B13: vsg_core/audit/trail.py | C13: AuditTrail.record_correlation_chunk | D13: Method | E13: Record a single correlation chunk result. | G13: Not Started | H13: Medium
B14: vsg_core/audit/trail.py | C14: AuditTrail.record_delay_calculation | D14: Method | E14: Record the delay calculation chain for a source. | G14: Not Started | H14: Medium
B15: vsg_core/audit/trail.py | C15: AuditTrail.record_final_delay | D15: Method | E15: Record final delay for a source (after global shift applied). | G15: Not Started | H15: Medium
B16: vsg_core/audit/trail.py | C16: AuditTrail.record_global_shift | D16: Method | E16: Record global shift calculation. | G16: Not Started | H16: Medium
B17: vsg_core/audit/trail.py | C17: AuditTrail.record_mux_tokens | D17: Method | E17: Record the final mkvmerge tokens. | F17: MKVToolNix integration | G17: Not Started | H17: Medium
B18: vsg_core/audit/trail.py | C18: AuditTrail.record_mux_track_delay | D18: Method | E18: Record the final delay calculation for a track in mux. | G18: Not Started | H18: Medium
B19: vsg_core/audit/trail.py | C19: AuditTrail.record_source | D19: Method | E19: Record source file information. | F19: Path handling | G19: Not Started | H19: Medium
B20: vsg_core/audit/trail.py | C20: AuditTrail.record_subtitle_parsed | D20: Method | E20: Record parsed subtitle info. | F20: Path handling | G20: Not Started | H20: Medium
B21: vsg_core/audit/trail.py | C21: AuditTrail.record_subtitle_sync | D21: Method | E21: Record subtitle sync operation details. | G21: Not Started | H21: Medium
B22: vsg_core/audit/trail.py | C22: AuditTrail.record_subtitle_track | D22: Method | E22: Record or update subtitle track processing data. | F22: Path handling | G22: Not Started | H22: Medium
B23: vsg_core/audit/trail.py | C23: AuditTrail.to_dict | D23: Method | E23: Return copy of the audit data. | G23: Not Started | H23: Medium
B24: vsg_core/audit/trail.py | C24: NumpyJSONEncoder.default | D24: Method | E24: Method of NumpyJSONEncoder | F24: Error handling, Path handling | G24: Not Started | H24: Medium
B25: vsg_core/postprocess/__init__.py | C25: __init__ | D25: Module | E25: Module initialization/configuration | G25: Not Started | H25: High
B26: vsg_core/postprocess/auditors/__init__.py | C26: __init__ | D26: Module | E26: Module initialization/configuration | G26: Not Started | H26: High
B27: vsg_core/postprocess/auditors/attachments.py | C27: AttachmentsAuditor | D27: Class | E27: Checks if expected attachments are present with correct filenames and reasonable sizes. | G27: Not Started | H27: High
B28: vsg_core/postprocess/auditors/attachments.py | C28: AttachmentsAuditor._verify_attachments | D28: Method | E28: Verify expected attachments are in the final file with correct names and reasonable sizes. | F28: Logging | G28: Not Started | H28: Medium
B29: vsg_core/postprocess/auditors/attachments.py | C29: AttachmentsAuditor.run | D29: Method | E29: Comprehensive attachment audit: | F29: Error handling, Logging, FFmpeg integration, MKVToolNix integration, Path handling | G29: Not Started | H29: High
B30: vsg_core/postprocess/auditors/audio_channels.py | C30: AudioChannelsAuditor | D30: Class | E30: Verifies channel counts and layouts weren't altered during muxing. | G30: Not Started | H30: High
B31: vsg_core/postprocess/auditors/audio_channels.py | C31: AudioChannelsAuditor._get_audio_stream_index_from_track_id | D31: Method | E31: Maps an mkvmerge track ID to the corresponding audio stream index in ffprobe output. | F31: FFmpeg integration, MKVToolNix integration | G31: Not Started | H31: Medium
B32: vsg_core/postprocess/auditors/audio_channels.py | C32: AudioChannelsAuditor.run | D32: Method | E32: Audits audio channel layouts to detect downmixing. | F32: Logging, FFmpeg integration, MKVToolNix integration, Path handling | G32: Not Started | H32: High
B33: vsg_core/postprocess/auditors/audio_object_based.py | C33: AudioObjectBasedAuditor | D33: Class | E33: Detailed object-based audio check (Atmos, DTS:X). | G33: Not Started | H33: High
B34: vsg_core/postprocess/auditors/audio_object_based.py | C34: AudioObjectBasedAuditor._get_audio_stream_index_from_track_id | D34: Method | E34: Maps an mkvmerge track ID to the corresponding audio stream index in ffprobe output. | F34: FFmpeg integration, MKVToolNix integration | G34: Not Started | H34: Medium
B35: vsg_core/postprocess/auditors/audio_object_based.py | C35: AudioObjectBasedAuditor.run | D35: Method | E35: Audits object-based audio metadata (Atmos/DTS:X). | F35: Logging, FFmpeg integration, MKVToolNix integration, Path handling | G35: Not Started | H35: High
B36: vsg_core/postprocess/auditors/audio_quality.py | C36: AudioQualityAuditor | D36: Class | E36: Checks for audio quality degradation (sample rate, bit depth changes). | G36: Not Started | H36: High
B37: vsg_core/postprocess/auditors/audio_quality.py | C37: AudioQualityAuditor._get_audio_stream_index_from_track_id | D37: Method | E37: Maps an mkvmerge track ID to the corresponding audio stream index in ffprobe output. | F37: FFmpeg integration, MKVToolNix integration | G37: Not Started | H37: Medium
B38: vsg_core/postprocess/auditors/audio_quality.py | C38: AudioQualityAuditor.run | D38: Method | E38: Audits audio quality parameters. | F38: Error handling, Logging, FFmpeg integration, MKVToolNix integration, Path handling | G38: Not Started | H38: High
B39: vsg_core/postprocess/auditors/audio_sync.py | C39: AudioSyncAuditor | D39: Class | E39: Verifies that audio sync delays in the final file match what was calculated. | G39: Not Started | H39: High
B40: vsg_core/postprocess/auditors/audio_sync.py | C40: AudioSyncAuditor._verify_codec_delay | D40: Method | E40: Primary verification: Check codec_delay in container metadata. | F40: Logging, MKVToolNix integration | G40: Not Started | H40: Medium
...

Sheet Main Window & Workers
A1: Done | B1: File Path | C1: Function/Class/Feature | D1: Type | E1: Description | F1: Features | G1: Status | H1: Priority | I1: Dependencies | J1: Notes | K1: New Implementation Path
B2: vsg_qt/main_window/__init__.py | C2: __init__ | D2: Module | E2: Module initialization/configuration | G2: Not Started | H2: High
B3: vsg_qt/main_window/controller.py | C3: MainController | D3: Class | E3: Class definition | G3: Not Started | H3: High
B4: vsg_qt/main_window/controller.py | C4: MainController.__init__ | D4: Method | E4: Method of MainController | F4: Logging, UI component | G4: Not Started | H4: High
B5: vsg_qt/main_window/controller.py | C5: MainController._archive_logs_for_batch | D5: Method | E5: Method of MainController | F5: Supports batch processing, Error handling, Logging, Path handling | G5: Not Started | H5: Medium
B6: vsg_qt/main_window/controller.py | C6: MainController._run_configured_jobs | D6: Method | E6: Method of MainController | F6: Supports batch processing, Path handling | G6: Not Started | H6: High
B7: vsg_qt/main_window/controller.py | C7: MainController._start_worker | D7: Method | E7: Method of MainController | F7: Supports batch processing, Multi-threaded, Logging, Path handling, Qt signals | G7: Not Started | H7: Medium
B8: vsg_qt/main_window/controller.py | C8: MainController.append_log | D8: Method | E8: Method of MainController | F8: Logging | G8: Not Started | H8: Medium
B9: vsg_qt/main_window/controller.py | C9: MainController.apply_config_to_ui | D9: Method | E9: Method of MainController | F9: Logging, Path handling | G9: Not Started | H9: Medium
B10: vsg_qt/main_window/controller.py | C10: MainController.batch_finished | D10: Method | E10: Method of MainController | F10: Handles single file mode, Supports batch processing, Logging, Path handling, UI component | G10: Not Started | H10: Medium
B11: vsg_qt/main_window/controller.py | C11: MainController.browse_for_path | D11: Method | E11: Method of MainController | F11: Logging, Path handling, UI component | G11: Not Started | H11: Medium
B12: vsg_qt/main_window/controller.py | C12: MainController.job_finished | D12: Method | E12: Method of MainController | F12: Logging | G12: Not Started | H12: Medium
B13: vsg_qt/main_window/controller.py | C13: MainController.on_close | D13: Method | E13: Method of MainController | F13: Logging, Qt signals | G13: Not Started | H13: Medium
B14: vsg_qt/main_window/controller.py | C14: MainController.open_job_queue | D14: Method | E14: Method of MainController | F14: Logging, UI component | G14: Not Started | H14: Medium
B15: vsg_qt/main_window/controller.py | C15: MainController.open_options_dialog | D15: Method | E15: Method of MainController | F15: Logging, UI component | G15: Not Started | H15: Medium
... B17: vsg_qt/main_window/controller.py | C17: MainController.start_batch_analyze_only | D17: Method | E17: Method of MainController | F17: Supports batch processing, Error handling, Path handling | G17: Not Started | H17: Medium
B18: vsg_qt/main_window/controller.py | C18: MainController.update_progress | D18: Method | E18: Method of MainController | G18: Not Started | H18: Medium
B19: vsg_qt/main_window/controller.py | C19: MainController.update_status | D19: Method | E19: Method of MainController | G19: Not Started | H19: Medium
B20: vsg_qt/main_window/window.py | C20: MainWindow | D20: Class | E20: Slim UI shell: builds widgets & delegates logic to MainController. | G20: Not Started | H20: High
B21: vsg_qt/main_window/window.py | C21: MainWindow.__init__ | D21: Method | E21: Method of MainWindow | F21: UI component | G21: Not Started | H21: High
B22: vsg_qt/main_window/window.py | C22: MainWindow._build_ui | D22: Method | E22: Method of MainWindow | F22: Supports batch processing, Logging, Path handling, Qt signals, UI component | G22: Not Started | H22: Medium
B23: vsg_qt/main_window/window.py | C23: MainWindow._create_file_input | D23: Method | E23: Method of MainWindow | F23: UI component | G23: Not Started | H23: Medium
B24: vsg_qt/main_window/window.py | C24: MainWindow.closeEvent | D24: Method | E24: Method of MainWindow | G24: Not Started | H24: Medium
B25: vsg_qt/worker/__init__.py | C25: __init__ | D25: Module | E25: Module initialization/configuration | G25: Not Started | H25: High
B26: vsg_qt/worker/runner.py | C26: JobWorker | D26: Class | E26: Class definition | G26: Not Started | H26: High
B27: vsg_qt/worker/runner.py | C27: JobWorker.__init__ | D27: Method | E27: Method of JobWorker | F27: Qt signals | G27: Not Started | H27: High
B28: vsg_qt/worker/runner.py | C28: JobWorker._safe_finished_all | D28: Method | E28: Safely emit all jobs finished signal, handling case where signals are deleted during GUI shutdown. | F28: Error handling, Qt signals | G28: Not Started | H28: Medium
B29: vsg_qt/worker/runner.py | C29: JobWorker._safe_finished_job | D29: Method | E29: Safely emit job finished signal, handling case where signals are deleted during GUI shutdown. | F29: Error handling, Qt signals | G29: Not Started | H29: Medium
B30: vsg_qt/worker/runner.py | C30: JobWorker._safe_log | D30: Method | E30: Safely emit log message, handling case where signals are deleted during GUI shutdown. | F30: Error handling, Logging, Qt signals | G30: Not Started | H30: Medium
B31: vsg_qt/worker/runner.py | C31: JobWorker._safe_progress | D31: Method | E31: Safely emit progress update, handling case where signals are deleted during GUI shutdown. | F31: Error handling, Qt signals | G31: Not Started | H31: Medium
B32: vsg_qt/worker/runner.py | C32: JobWorker._safe_status | D32: Method | E32: Safely emit status update, handling case where signals are deleted during GUI shutdown. | F32: Error handling, Qt signals | G32: Not Started | H32: Medium
B33: vsg_qt/worker/runner.py | C33: JobWorker.cancel | D33: Method | E33: Request cancellation of this worker. | G33: Not Started | H33: Medium
B34: vsg_qt/worker/runner.py | C34: JobWorker.run | D34: Method | E34: Method of JobWorker | F34: Supports batch processing, Error handling, Logging, Path handling | G34: Not Started | H34: High
B35: vsg_qt/worker/signals.py | C35: WorkerSignals | D35: Class | E35: Defines the signals available from a running worker thread. | G35: Not Started | H35: High

Sheet Dialogs
A1: Done | B1: File Path | C1: Function/Class/Feature | D1: Type | E1: Description | F1: Features | G1: Status | H1: Priority | I1: Dependencies | J1: Notes | K1: New Implementation Path
B2: vsg_qt/add_job_dialog/__init__.py | C2: __init__ | D2: Module | E2: Module initialization/configuration | G2: Not Started | H2: High
B3: vsg_qt/add_job_dialog/ui.py | C3: AddJobDialog | D3: Class | E3: A dialog for dynamically adding sources to discover jobs. | G3: Not Started | H3: High
B4: vsg_qt/add_job_dialog/ui.py | C4: SourceInputWidget | D4: Class | E4: A self-contained widget for a single source input row that handles drag-and-drop. | G4: Not Started | H4: High
B5: vsg_qt/add_job_dialog/ui.py | C5: AddJobDialog.__init__ | D5: Method | E5: Method of AddJobDialog | F5: UI component | G5: Not Started | H5: High
B6: vsg_qt/add_job_dialog/ui.py | C6: AddJobDialog._build_ui | D6: Method | E6: Method of AddJobDialog | F6: Logging, UI component | G6: Not Started | H6: Medium
B7: vsg_qt/add_job_dialog/ui.py | C7: AddJobDialog.add_source_input | D7: Method | E7: Adds a new SourceInputWidget to the dialog. | F7: Logging, UI component | G7: Not Started | H7: Medium
B8: vsg_qt/add_job_dialog/ui.py | C8: AddJobDialog.find_and_accept | D8: Method | E8: Discover jobs from paths and accept the dialog if any are found. | F8: Error handling, Logging, Path handling, UI component | G8: Not Started | H8: Medium
B9: vsg_qt/add_job_dialog/ui.py | C9: AddJobDialog.get_discovered_jobs | D9: Method | E9: Method of AddJobDialog | G9: Not Started | H9: Medium
B10: vsg_qt/add_job_dialog/ui.py | C10: AddJobDialog.populate_sources_from_paths | D10: Method | E10: Pre-fills the source inputs from a list of paths. | F10: Path handling, UI component | G10: Not Started | H10: Medium
B11: vsg_qt/add_job_dialog/ui.py | C11: SourceInputWidget.__init__ | D11: Method | E11: Method of SourceInputWidget | F11: Path handling, UI component | G11: Not Started | H11: High
B12: vsg_qt/add_job_dialog/ui.py | C12: SourceInputWidget._browse_for_path | D12: Method | E12: Method of SourceInputWidget | F12: Logging, Path handling, UI component | G12: Not Started | H12: Medium
B13: vsg_qt/add_job_dialog/ui.py | C13: SourceInputWidget.dragEnterEvent | D13: Method | E13: Method of SourceInputWidget | G13: Not Started | H13: Medium
B14: vsg_qt/add_job_dialog/ui.py | C14: SourceInputWidget.dropEvent | D14: Method | E14: Method of SourceInputWidget | F14: Path handling | G14: Not Started | H14: Medium
B15: vsg_qt/add_job_dialog/ui.py | C15: SourceInputWidget.text | D15: Method | E15: Method of SourceInputWidget | G15: Not Started | H15: Medium
B16: vsg_qt/favorites_dialog/__init__.py | C16: __init__ | D16: Module | E16: Module initialization/configuration | G16: Not Started | H16: High
B17: vsg_qt/favorites_dialog/ui.py | C17: ColorSwatchWidget | D17: Class | E17: A small widget that displays a color swatch. | G17: Not Started | H17: High
B18: vsg_qt/favorites_dialog/ui.py | C18: FavoritesManagerDialog | D18: Class | E18: Dialog for managing favorite colors. | G18: Not Started | H18: High
B19: vsg_qt/favorites_dialog/ui.py | C19: ColorSwatchWidget.__init__ | D19: Method | E19: Method of ColorSwatchWidget | G19: Not Started | H19: High
B20: vsg_qt/favorites_dialog/ui.py | C20: ColorSwatchWidget.set_color | D20: Method | E20: Method of ColorSwatchWidget | G20: Not Started | H20: Medium
B21: vsg_qt/favorites_dialog/ui.py | C21: FavoritesManagerDialog.__init__ | D21: Method | E21: Method of FavoritesManagerDialog | F21: Qt signals, UI component | G21: Not Started | H21: High
B22: vsg_qt/favorites_dialog/ui.py | C22: FavoritesManagerDialog._build_ui | D22: Method | E22: Method of FavoritesManagerDialog | F22: UI component | G22: Not Started | H22: Medium
B23: vsg_qt/favorites_dialog/ui.py | C23: FavoritesManagerDialog._connect_signals | D23: Method | E23: Method of FavoritesManagerDialog | F23: Qt signals | G23: Not Started | H23: Medium
B24: vsg_qt/favorites_dialog/ui.py | C24: FavoritesManagerDialog._on_add_color | D24: Method | E24: Add a new favorite color. | F24: Logging, UI component | G24: Not Started | H24: Medium
